Workbook

Sheet Resources
B1: Race 1 | C1: Race 2 | D1: Race 3 | E1: Race 4 | F1: Race 5 | G1: Race 6 | H1: Race 7 | I1: Race 8 | J1: Race 9 | K1: Race 10 | L1: Race 11 | M1: Race 12 | N1: Race 13 | O1: Race 14 | P1: Race 15 | Q1: Race 16
A3: Race Name | C3: Boston Marathon | E3: Chicago Marathon | J3: London 2027
A4: Race Date | C4: 46132 | E4: 46306 | J4: 2027
A5: Notes
A6: Priority | C6: MAIN | E6: MAIN | J6: MAYBE
A7: Distance | C7: Marathon | E7: Marathon
A8: A Goal | C8: 0.13888889
A9: Mile Pace | B9: =IFerror(IFS(B7="100 Mile", B8/100,B7="100k",B8/62, B7="50 mile",B8/50, B7="50k",B8/31, B7="marathon",B8/26.2, B7="30k",B8/18.6, B7="25k",B8/15.5, B7="Half Marathon",B8/13.1, B7="10 Mile",B8/10, B7="15k",B8/9.3, B7="10k",B8/6.2, B7="8k",B8/5, B7="5k",B8/3.12, B7="1 Mile",B8/1),"") | C9: =IFerror(IFS(C7="100 Mile", C8/100,C7="100k",C8/62, C7="50 mile",C8/50, C7="50k",C8/31, C7="marathon",C8/26.2, C7="30k",C8/18.6, C7="25k",C8/15.5, C7="Half Marathon",C8/13.1, C7="10 Mile",C8/10, C7="15k",C8/9.3, C7="10k",C8/6.2, C7="8k",C8/5, C7="5k",C8/3.12, C7="1 Mile",C8/1),"") -> 0.0053011026 | D9: =IFerror(IFS(D7="100 Mile", D8/100,D7="100k",D8/62, D7="50 mile",D8/50, D7="50k",D8/31, D7="marathon",D8/26.2, D7="30k",D8/18.6, D7="25k",D8/15.5, D7="Half Marathon",D8/13.1, D7="10 Mile",D8/10, D7="15k",D8/9.3, D7="10k",D8/6.2, D7="8k",D8/5, D7="5k",D8/3.12, D7="1 Mile",D8/1),"") | E9: =IFerror(IFS(E7="100 Mile", E8/100,E7="100k",E8/62, E7="50 mile",E8/50, E7="50k",E8/31, E7="marathon",E8/26.2, E7="30k",E8/18.6, E7="25k",E8/15.5, E7="Half Marathon",E8/13.1, E7="10 Mile",E8/10, E7="15k",E8/9.3, E7="10k",E8/6.2, E7="8k",E8/5, E7="5k",E8/3.12, E7="1 Mile",E8/1),"") -> 0 | F9: =IFerror(IFS(F7="100 Mile", F8/100,F7="100k",F8/62, F7="50 mile",F8/50, F7="50k",F8/31, F7="marathon",F8/26.2, F7="30k",F8/18.6, F7="25k",F8/15.5, F7="Half Marathon",F8/13.1, F7="10 Mile",F8/10, F7="15k",F8/9.3, F7="10k",F8/6.2, F7="8k",F8/5, F7="5k",F8/3.12, F7="1 Mile",F8/1),"") | G9: =IFerror(IFS(G7="100 Mile", G8/100,G7="100k",G8/62, G7="50 mile",G8/50, G7="50k",G8/31, G7="marathon",G8/26.2, G7="30k",G8/18.6, G7="25k",G8/15.5, G7="Half Marathon",G8/13.1, G7="10 Mile",G8/10, G7="15k",G8/9.3, G7="10k",G8/6.2, G7="8k",G8/5, G7="5k",G8/3.12, G7="1 Mile",G8/1),"") | H9: =IFerror(IFS(H7="100 Mile", H8/100,H7="100k",H8/62, H7="50 mile",H8/50, H7="50k",H8/31, H7="marathon",H8/26.2, H7="30k",H8/18.6, H7="25k",H8/15.5, H7="Half Marathon",H8/13.1, H7="10 Mile",H8/10, H7="15k",H8/9.3, H7="10k",H8/6.2, H7="8k",H8/5, H7="5k",H8/3.12, H7="1 Mile",H8/1),"") | I9: =IFerror(IFS(I7="100 Mile", I8/100,I7="100k",I8/62, I7="50 mile",I8/50, I7="50k",I8/31, I7="marathon",I8/26.2, I7="30k",I8/18.6, I7="25k",I8/15.5, I7="Half Marathon",I8/13.1, I7="10 Mile",I8/10, I7="15k",I8/9.3, I7="10k",I8/6.2, I7="8k",I8/5, I7="5k",I8/3.12, I7="1 Mile",I8/1),"") | ... Q9: =IFerror(IFS(Q7="100 Mile", Q8/100,Q7="100k",Q8/62, Q7="50 mile",Q8/50, Q7="50k",Q8/31, Q7="marathon",Q8/26.2, Q7="30k",Q8/18.6, Q7="25k",Q8/15.5, Q7="Half Marathon",Q8/13.1, Q7="10 Mile",Q8/10, Q7="15k",Q8/9.3, Q7="10k",Q8/6.2, Q7="8k",Q8/5, Q7="5k",Q8/3.12, Q7="1 Mile",Q8/1),"")
A10: Km Pace | B10: =B9/1.6 -> 0 | C10: =C9/1.6 -> 0.0033131891 | D10: =D9/1.6 -> 0 | E10: =E9/1.6 -> 0 | F10: =F9/1.6 -> 0 | G10: =G9/1.6 -> 0 | H10: =H9/1.6 -> 0 | I10: =I9/1.6 -> 0 | ... Q10: =Q9/1.6 -> 0
A11: B Goal | C11: 0.13541667
A12: Mile Pace | B12: =IFerror(IFS(B7="100 Mile", B11/100,B7="100k",B11/62, B7="50 mile",B11/50, B7="50k",B11/31, B7="marathon",B11/26.2, B7="30k",B11/18.6, B7="25k",B11/15.5, B7="Half Marathon",B11/13.1, B7="10 Mile",B11/10, B7="15k",B11/9.3, B7="10k",B11/6.2, B7="8k",B11/5, B7="5k",B11/3.12, B7="1 Mile",B11/1),"") | C12: =IFerror(IFS(C7="100 Mile", C11/100,C7="100k",C11/62, C7="50 mile",C11/50, C7="50k",C11/31, C7="marathon",C11/26.2, C7="30k",C11/18.6, C7="25k",C11/15.5, C7="Half Marathon",C11/13.1, C7="10 Mile",C11/10, C7="15k",C11/9.3, C7="10k",C11/6.2, C7="8k",C11/5, C7="5k",C11/3.12, C7="1 Mile",C11/1),"") -> 0.0051685751 | D12: =IFerror(IFS(D7="100 Mile", D11/100,D7="100k",D11/62, D7="50 mile",D11/50, D7="50k",D11/31, D7="marathon",D11/26.2, D7="30k",D11/18.6, D7="25k",D11/15.5, D7="Half Marathon",D11/13.1, D7="10 Mile",D11/10, D7="15k",D11/9.3, D7="10k",D11/6.2, D7="8k",D11/5, D7="5k",D11/3.12, D7="1 Mile",D11/1),"") | E12: =IFerror(IFS(E7="100 Mile", E11/100,E7="100k",E11/62, E7="50 mile",E11/50, E7="50k",E11/31, E7="marathon",E11/26.2, E7="30k",E11/18.6, E7="25k",E11/15.5, E7="Half Marathon",E11/13.1, E7="10 Mile",E11/10, E7="15k",E11/9.3, E7="10k",E11/6.2, E7="8k",E11/5, E7="5k",E11/3.12, E7="1 Mile",E11/1),"") -> 0 | F12: =IFerror(IFS(F7="100 Mile", F11/100,F7="100k",F11/62, F7="50 mile",F11/50, F7="50k",F11/31, F7="marathon",F11/26.2, F7="30k",F11/18.6, F7="25k",F11/15.5, F7="Half Marathon",F11/13.1, F7="10 Mile",F11/10, F7="15k",F11/9.3, F7="10k",F11/6.2, F7="8k",F11/5, F7="5k",F11/3.12, F7="1 Mile",F11/1),"") | G12: =IFerror(IFS(G7="100 Mile", G11/100,G7="100k",G11/62, G7="50 mile",G11/50, G7="50k",G11/31, G7="marathon",G11/26.2, G7="30k",G11/18.6, G7="25k",G11/15.5, G7="Half Marathon",G11/13.1, G7="10 Mile",G11/10, G7="15k",G11/9.3, G7="10k",G11/6.2, G7="8k",G11/5, G7="5k",G11/3.12, G7="1 Mile",G11/1),"") | H12: =IFerror(IFS(H7="100 Mile", H11/100,H7="100k",H11/62, H7="50 mile",H11/50, H7="50k",H11/31, H7="marathon",H11/26.2, H7="30k",H11/18.6, H7="25k",H11/15.5, H7="Half Marathon",H11/13.1, H7="10 Mile",H11/10, H7="15k",H11/9.3, H7="10k",H11/6.2, H7="8k",H11/5, H7="5k",H11/3.12, H7="1 Mile",H11/1),"") | I12: =IFerror(IFS(I7="100 Mile", I11/100,I7="100k",I11/62, I7="50 mile",I11/50, I7="50k",I11/31, I7="marathon",I11/26.2, I7="30k",I11/18.6, I7="25k",I11/15.5, I7="Half Marathon",I11/13.1, I7="10 Mile",I11/10, I7="15k",I11/9.3, I7="10k",I11/6.2, I7="8k",I11/5, I7="5k",I11/3.12, I7="1 Mile",I11/1),"") | ... Q12: =IFerror(IFS(Q7="100 Mile", Q11/100,Q7="100k",Q11/62, Q7="50 mile",Q11/50, Q7="50k",Q11/31, Q7="marathon",Q11/26.2, Q7="30k",Q11/18.6, Q7="25k",Q11/15.5, Q7="Half Marathon",Q11/13.1, Q7="10 Mile",Q11/10, Q7="15k",Q11/9.3, Q7="10k",Q11/6.2, Q7="8k",Q11/5, Q7="5k",Q11/3.12, Q7="1 Mile",Q11/1),"")
A13: Km Pace | B13: =B12/1.6 -> 0 | C13: =C12/1.6 -> 0.0032303594 | D13: =D12/1.6 -> 0 | E13: =E12/1.6 -> 0 | F13: =F12/1.6 -> 0 | G13: =G12/1.6 -> 0 | H13: =H12/1.6 -> 0 | I13: =I12/1.6 -> 0 | ... Q13: =Q12/1.6 -> 0
A14: First Race? | C14: No | E14: No
A15: Course Type | C15: Semi-Hilly | E15: Flat
A16: Race Website | B16: LINK | C16: LINK | D16: LINK | E16: LINK | F16: LINK | G16: LINK | H16: LINK | I16: LINK | J16: LINK | K16: LINK | L16: LINK | M16: LINK | N16: LINK | O16: LINK | P16: LINK | Q16: LINK
A17: Result
A18: PRs BEFORE VERTIS | B18: TIME | C18: RACE | D18: PACE | E18: DATE | F18: NEW PERSONAL RECORDS/ RACES
F19: RACE | H19: DATE | I19: TIME | J19: PR? | K19: PR AMOUNT | L19: RACE | N19: DATE | O19: TIME | P19: PR? | Q19: PR AMOUNT
A20: 100 Miler | D20: =B20/100 -> 0 | F20: Go Hard or Go home Half | H20: 3/22/25 | I20: 1:35:35 | J20: Yes | K20: 3:18
A21: 100k | D21: =B21/62.13 -> 0 | F21: Toronto Marathon | H21: 5/4/25 | I21: 3:18:00 | J21: Yes | K21: 8:58
A22: 50k | D22: =B22/31 -> 0
A23: Marathon | B23: 3:26 | C23: Toronto Marathon | D23: =B23/26.2 -> 0.0054601357
A24: 30km | D24: =B24/18.6 -> 0
A25: 25km | D25: =B25/15.5 -> 0
A26: Half | B26: 1:38:53 | C26: NY United Half | D26: =B26/13.1 -> 0.005241907 | E26: 3/19/23
A27: 10 Mile | D27: =B27/10 -> 0
A28: 15k | D28: =B28/9.3 -> 0
A29: 10k | D29: =B29/6.2 -> 0
A30: 8k | D30: =B30/5 -> 0
A31: 5k | D31: =B31/3.12 -> 0
A32: 2 mile | D32: =B32/2 -> 0
A33: 1 Mile | D33: =B33/1 -> 0
A34: COACHES NOTES | J34: RESOURCES | L34: PERSONAL SPECIFICS
A35: 46023 | D35: 46023 | G35: 46023 | J35: Google Sheets Android App | L35: Watch
L37: HR MONITOR
A39: 46023 | D39: 46023 | G39: 46023 | J39: Google Sheets IOS App | L39: Treadmill/ Bike Access
L41: Easy Run Shoes
A43: 46023 | D43: 46023 | G43: 46023 | J43: HOW TO USE YOUR PLAN | L43: Steady/ Long Run Shoes
L45: Hard Workout Shoes
A47: 46023 | D47: 46023 | G47: 46023 | J47: SHOES/ GEAR INFO | L47: Race Day Shoes
...

Sheet Fueling
A1: Marathon Fuel Tracker 1 | C1: Date ➡️ | D1: 46023 | E1: Workout/ Race ➡️ | K1: Half Fuel Tracker 1 | M1: Date ➡️ | N1: 46023 | O1: Workout/ Race ➡️
E2: Other Notes ➡️ | O2: Other Notes ➡️
A3: Time | B3: Fuel | C3: Caffeine | D3: Sodium (mg) | E3: Carbs (g) | F3: Cumulative Carbs (g) | G3: Carbs/ hr | H3: How it went | I3: Notes | K3: Time | L3: Fuel | M3: Caffeine | N3: Sodium (mg) | O3: Carbs (g) | P3: Cumulative Carbs (g) | Q3: Carbs/ hr | R3: How it went | S3: Notes
F4: =SUM(E4) -> 0 | P4: =SUM(O4) -> 0
F5: =SUM(E4:E5) -> 0 | P5: =SUM(O4:O5) -> 0
F6: =SUM(E4:E6) -> 0 | P6: =SUM(O4:O6) -> 0
F7: =SUM(E4:E7) -> 0 | P7: =SUM(O4:O7) -> 0
F8: =SUM(E4:E8) -> 0 | P8: =SUM(O4:O8) -> 0
F9: =SUM(E4:E9) -> 0 | P9: =SUM(O4:O9) -> 0
F10: =SUM(E4:E10) -> 0 | P10: =SUM(O4:O10) -> 0
F11: =SUM(E4:E11) -> 0 | P11: =SUM(O4:O11) -> 0
F12: =SUM(E4:E12) -> 0 | P12: =SUM(O4:O12) -> 0
F13: =SUM(E4:E13) -> 0 | P13: =SUM(O4:O13) -> 0
F14: =SUM(E4:E14) -> 0 | P14: =SUM(O4:O14) -> 0
F15: =SUM(E4:E15) -> 0 | P15: =SUM(O4:O15) -> 0
F16: =SUM(E4:E16) -> 0 | P16: =SUM(O4:O16) -> 0
F17: =SUM(E4:E17) -> 0 | P17: =SUM(O4:O17) -> 0
F18: =SUM(E4:E18) -> 0 | P18: =SUM(O4:O18) -> 0
F19: =SUM(E4:E19) -> 0 | P19: =SUM(O4:O19) -> 0
F20: =SUM(E4:E20) -> 0 | P20: =SUM(O4:O20) -> 0
F21: =SUM(E5:E21,E4) -> 0 | P21: =SUM(O5:O21,O4) -> 0
A23: Marathon Fuel Tracker 2 | C23: Date ➡️ | D23: 46023 | E23: Workout/ Race ➡️ | K23: Half Fuel Tracker 2 | M23: Date ➡️ | N23: 46023 | O23: Workout/ Race ➡️
E24: Other Notes ➡️ | O24: Other Notes ➡️
A25: Time | B25: Fuel | C25: Caffeine | D25: Sodium (mg) | E25: Carbs (g) | F25: Cumulative Carbs (g) | G25: Carbs/ hr | H25: How it went | I25: Notes | K25: Time | L25: Fuel | M25: Caffeine | N25: Sodium (mg) | O25: Carbs (g) | P25: Cumulative Carbs (g) | Q25: Carbs/ hr | R25: How it went | S25: Notes
F26: =SUM(E26) -> 0 | P26: =SUM(O26) -> 0
F27: =SUM(E26:E27) -> 0 | P27: =SUM(O26:O27) -> 0
F28: =SUM(E26:E28) -> 0 | P28: =SUM(O26:O28) -> 0
F29: =SUM(E26:E29) -> 0 | P29: =SUM(O26:O29) -> 0
F30: =SUM(E26:E30) -> 0 | P30: =SUM(O26:O30) -> 0
F31: =SUM(E26:E31) -> 0 | P31: =SUM(O26:O31) -> 0
F32: =SUM(E26:E32) -> 0 | P32: =SUM(O26:O32) -> 0
F33: =SUM(E26:E33) -> 0 | P33: =SUM(O26:O33) -> 0
F34: =SUM(E26:E34) -> 0 | P34: =SUM(O26:O34) -> 0
F35: =SUM(E26:E35) -> 0 | P35: =SUM(O26:O35) -> 0
F36: =SUM(E26:E36) -> 0 | P36: =SUM(O26:O36) -> 0
F37: =SUM(E26:E37) -> 0 | P37: =SUM(O26:O37) -> 0
F38: =SUM(E26:E38) -> 0 | P38: =SUM(O26:O38) -> 0
F39: =SUM(E26:E39) -> 0 | P39: =SUM(O26:O39) -> 0
F40: =SUM(E26:E40) -> 0 | P40: =SUM(O26:O40) -> 0
F41: =SUM(E26:E41) -> 0 | P41: =SUM(O26:O41) -> 0
...

Sheet Strength
A1: Needs Work | B1: Strength Workout 1 | D1: Warm-Up VIDEO | E1: Date | F1: Workout 1 Data | I1: Date | J1: Workout 2 Data | M1: Date | N1: Workout 3 Data | Q1: Date | R1: Workout 4 Data | U1: Date | V1: Workout 5 Data | Y1: Date | Z1: Workout 6 Data | AC1: Date | AD1: Workout 7 Data | AG1: Date | AH1: Workout 8 Data | AK1: Date | AL1: Workout 9 Data | AO1: Date | AP1: Workout 10 Data | AS1: Date | AT1: Workout 11 Data | AW1: Date | AX1: Workout 12 Data | BA1: Date | BB1: Workout 13 Data | BE1: Date | BF1: Workout 14 Data | BI1: Date | BJ1: Workout 15 Data | BM1: Date | BN1: Workout 17 Data | BQ1: Date | BR1: Workout 18 Data | BU1: Date | BV1: Workout 19 Data | BY1: Date | BZ1: Workout 20 Data | CC1: Date | CD1: Workout 21 Data | CG1: Date | CH1: Workout 22 Data
E3: 46023 | F3: Weight | G3: Reps | I3: 46023 | J3: Weight | K3: Reps | M3: 46023 | N3: Weight | O3: Reps | Q3: 46023 | R3: Weight | S3: Reps | U3: 46023 | V3: Weight | W3: Reps | Y3: 46023 | Z3: Weight | AA3: Reps | AC3: 46023 | AD3: Weight | AE3: Reps | AG3: 46023 | AH3: Weight | AI3: Reps | AK3: 46023 | AL3: Weight | AM3: Reps | AO3: 46023 | AP3: Weight | AQ3: Reps | AS3: 46023 | AT3: Weight | AU3: Reps | AW3: 46023 | AX3: Weight | AY3: Reps | BA3: 46023 | BB3: Weight | BC3: Reps | BE3: 46023 | BF3: Weight | BG3: Reps | BI3: 46023 | BJ3: Weight | BK3: Reps | BM3: 46023 | BN3: Weight | BO3: Reps | BQ3: 46023 | BR3: Weight | BS3: Reps | BU3: 46023 | BV3: Weight | BW3: Reps | BY3: 46023 | BZ3: Weight | CA3: Reps | CC3: 46023 | CD3: Weight | CE3: Reps | CG3: 46023 | CH3: Weight | CI3: Reps
A5: FALSE | B5: Overhead Weighted Sit-Ups; Seated Twist (Superset) | D5: LINK | E5: Notes ⬇️ | I5: Notes ⬇️ | M5: Notes ⬇️ | Q5: Notes ⬇️ | U5: Notes ⬇️ | Y5: Notes ⬇️ | AC5: Notes ⬇️ | AG5: Notes ⬇️ | AK5: Notes ⬇️ | AO5: Notes ⬇️ | AS5: Notes ⬇️ | AW5: Notes ⬇️ | BA5: Notes ⬇️ | BE5: Notes ⬇️ | BI5: Notes ⬇️ | BM5: Notes ⬇️ | BQ5: Notes ⬇️ | BU5: Notes ⬇️ | BY5: Notes ⬇️ | CC5: Notes ⬇️ | CG5: Notes ⬇️
B9: Sets | C9: Reps | D9: Weight
B10: 3 | C10: 8 - 12 | D10: 15 - 20 lbs | E10: Effort Level ➡️ | I10: Effort Level ➡️ | M10: Effort Level ➡️ | Q10: Effort Level ➡️ | U10: Effort Level ➡️ | Y10: Effort Level ➡️ | AC10: Effort Level ➡️ | AG10: Effort Level ➡️ | AK10: Effort Level ➡️ | AO10: Effort Level ➡️ | AS10: Effort Level ➡️ | AW10: Effort Level ➡️ | BA10: Effort Level ➡️ | BE10: Effort Level ➡️ | BI10: Effort Level ➡️ | BM10: Effort Level ➡️ | BQ10: Effort Level ➡️ | BU10: Effort Level ➡️ | BY10: Effort Level ➡️ | CC10: Effort Level ➡️ | CG10: Effort Level ➡️
A12: FALSE | B12: Pull-up Bar Leg Raises | D12: LINK | E12: Notes ⬇️ | I12: Notes ⬇️ | M12: Notes ⬇️ | Q12: Notes ⬇️ | U12: Notes ⬇️ | Y12: Notes ⬇️ | AC12: Notes ⬇️ | AG12: Notes ⬇️ | AK12: Notes ⬇️ | AO12: Notes ⬇️ | AS12: Notes ⬇️ | AW12: Notes ⬇️ | BA12: Notes ⬇️ | BE12: Notes ⬇️ | BI12: Notes ⬇️ | BM12: Notes ⬇️ | BQ12: Notes ⬇️ | BU12: Notes ⬇️ | BY12: Notes ⬇️ | CC12: Notes ⬇️ | CG12: Notes ⬇️
B16: Sets | C16: Reps | D16: Weight
B17: 3 | C17: 6 - 10 | D17: Bodyweight | E17: Effort Level ➡️ | I17: Effort Level ➡️ | M17: Effort Level ➡️ | Q17: Effort Level ➡️ | U17: Effort Level ➡️ | Y17: Effort Level ➡️ | AC17: Effort Level ➡️ | AG17: Effort Level ➡️ | AK17: Effort Level ➡️ | AO17: Effort Level ➡️ | AS17: Effort Level ➡️ | AW17: Effort Level ➡️ | BA17: Effort Level ➡️ | BE17: Effort Level ➡️ | BI17: Effort Level ➡️ | BM17: Effort Level ➡️ | BQ17: Effort Level ➡️ | BU17: Effort Level ➡️ | BY17: Effort Level ➡️ | CC17: Effort Level ➡️ | CG17: Effort Level ➡️
A19: FALSE | B19: Plank Pull-Throughs; Side Plank Leg Lift (Superset) | D19: LINK | E19: Notes ⬇️ | I19: Notes ⬇️ | M19: Notes ⬇️ | Q19: Notes ⬇️ | U19: Notes ⬇️ | Y19: Notes ⬇️ | AC19: Notes ⬇️ | AG19: Notes ⬇️ | AK19: Notes ⬇️ | AO19: Notes ⬇️ | AS19: Notes ⬇️ | AW19: Notes ⬇️ | BA19: Notes ⬇️ | BE19: Notes ⬇️ | BI19: Notes ⬇️ | BM19: Notes ⬇️ | BQ19: Notes ⬇️ | BU19: Notes ⬇️ | BY19: Notes ⬇️ | CC19: Notes ⬇️ | CG19: Notes ⬇️
B23: Sets | C23: Reps | D23: Weight
B24: 3 | C24: 8 - 12 | D24: 10 - 15 lbs | E24: Effort Level ➡️ | I24: Effort Level ➡️ | M24: Effort Level ➡️ | Q24: Effort Level ➡️ | U24: Effort Level ➡️ | Y24: Effort Level ➡️ | AC24: Effort Level ➡️ | AG24: Effort Level ➡️ | AK24: Effort Level ➡️ | AO24: Effort Level ➡️ | AS24: Effort Level ➡️ | AW24: Effort Level ➡️ | BA24: Effort Level ➡️ | BE24: Effort Level ➡️ | BI24: Effort Level ➡️ | BM24: Effort Level ➡️ | BQ24: Effort Level ➡️ | BU24: Effort Level ➡️ | BY24: Effort Level ➡️ | CC24: Effort Level ➡️ | CG24: Effort Level ➡️
A26: FALSE | B26: Dead Bugs (Each Side) | D26: LINK | E26: Notes ⬇️ | I26: Notes ⬇️ | M26: Notes ⬇️ | Q26: Notes ⬇️ | U26: Notes ⬇️ | Y26: Notes ⬇️ | AC26: Notes ⬇️ | AG26: Notes ⬇️ | AK26: Notes ⬇️ | AO26: Notes ⬇️ | AS26: Notes ⬇️ | AW26: Notes ⬇️ | BA26: Notes ⬇️ | BE26: Notes ⬇️ | BI26: Notes ⬇️ | BM26: Notes ⬇️ | BQ26: Notes ⬇️ | BU26: Notes ⬇️ | BY26: Notes ⬇️ | CC26: Notes ⬇️ | CG26: Notes ⬇️
B30: Sets | C30: Reps | D30: Weight
B31: 3 | C31: 8 - 12 | D31: Bodyweight | E31: Effort Level ➡️ | I31: Effort Level ➡️ | M31: Effort Level ➡️ | Q31: Effort Level ➡️ | U31: Effort Level ➡️ | Y31: Effort Level ➡️ | AC31: Effort Level ➡️ | AG31: Effort Level ➡️ | AK31: Effort Level ➡️ | AO31: Effort Level ➡️ | AS31: Effort Level ➡️ | AW31: Effort Level ➡️ | BA31: Effort Level ➡️ | BE31: Effort Level ➡️ | BI31: Effort Level ➡️ | BM31: Effort Level ➡️ | BQ31: Effort Level ➡️ | BU31: Effort Level ➡️ | BY31: Effort Level ➡️ | CC31: Effort Level ➡️ | CG31: Effort Level ➡️
A33: FALSE | B33: Bulgarian Split Squats | D33: LINK | E33: Notes ⬇️ | I33: Notes ⬇️ | M33: Notes ⬇️ | Q33: Notes ⬇️ | U33: Notes ⬇️ | Y33: Notes ⬇️ | AC33: Notes ⬇️ | AG33: Notes ⬇️ | AK33: Notes ⬇️ | AO33: Notes ⬇️ | AS33: Notes ⬇️ | AW33: Notes ⬇️ | BA33: Notes ⬇️ | BE33: Notes ⬇️ | BI33: Notes ⬇️ | BM33: Notes ⬇️ | BQ33: Notes ⬇️ | BU33: Notes ⬇️ | BY33: Notes ⬇️ | CC33: Notes ⬇️ | CG33: Notes ⬇️
B37: Sets | C37: Reps | D37: Weight
B38: 3 | C38: 8 - 12 | D38: 20 - 30 lbs | E38: Effort Level ➡️ | I38: Effort Level ➡️ | M38: Effort Level ➡️ | Q38: Effort Level ➡️ | U38: Effort Level ➡️ | Y38: Effort Level ➡️ | AC38: Effort Level ➡️ | AG38: Effort Level ➡️ | AK38: Effort Level ➡️ | AO38: Effort Level ➡️ | AS38: Effort Level ➡️ | AW38: Effort Level ➡️ | BA38: Effort Level ➡️ | BE38: Effort Level ➡️ | BI38: Effort Level ➡️ | BM38: Effort Level ➡️ | BQ38: Effort Level ➡️ | BU38: Effort Level ➡️ | BY38: Effort Level ➡️ | CC38: Effort Level ➡️ | CG38: Effort Level ➡️
A40: FALSE | B40: Weighted Calf Walks (Front/ Back/ Side-to-Side) | D40: LINK | E40: Notes ⬇️ | I40: Notes ⬇️ | M40: Notes ⬇️ | Q40: Notes ⬇️ | U40: Notes ⬇️ | Y40: Notes ⬇️ | AC40: Notes ⬇️ | AG40: Notes ⬇️ | AK40: Notes ⬇️ | AO40: Notes ⬇️ | AS40: Notes ⬇️ | AW40: Notes ⬇️ | BA40: Notes ⬇️ | BE40: Notes ⬇️ | BI40: Notes ⬇️ | BM40: Notes ⬇️ | BQ40: Notes ⬇️ | BU40: Notes ⬇️ | BY40: Notes ⬇️ | CC40: Notes ⬇️ | CG40: Notes ⬇️
B44: Sets | C44: Reps | D44: Weight
B45: 3 | C45: 20-30 sec | D45: 10 - 20 lbs | E45: Effort Level ➡️ | I45: Effort Level ➡️ | M45: Effort Level ➡️ | Q45: Effort Level ➡️ | U45: Effort Level ➡️ | Y45: Effort Level ➡️ | AC45: Effort Level ➡️ | AG45: Effort Level ➡️ | AK45: Effort Level ➡️ | AO45: Effort Level ➡️ | AS45: Effort Level ➡️ | AW45: Effort Level ➡️ | BA45: Effort Level ➡️ | BE45: Effort Level ➡️ | BI45: Effort Level ➡️ | BM45: Effort Level ➡️ | BQ45: Effort Level ➡️ | BU45: Effort Level ➡️ | BY45: Effort Level ➡️ | CC45: Effort Level ➡️ | CG45: Effort Level ➡️
A47: FALSE | B47: Weighted Split Stance Hip Opener | D47: LINK | E47: Notes ⬇️ | I47: Notes ⬇️ | M47: Notes ⬇️ | Q47: Notes ⬇️ | U47: Notes ⬇️ | Y47: Notes ⬇️ | AC47: Notes ⬇️ | AG47: Notes ⬇️ | AK47: Notes ⬇️ | AO47: Notes ⬇️ | AS47: Notes ⬇️ | AW47: Notes ⬇️ | BA47: Notes ⬇️ | BE47: Notes ⬇️ | BI47: Notes ⬇️ | BM47: Notes ⬇️ | BQ47: Notes ⬇️ | BU47: Notes ⬇️ | BY47: Notes ⬇️ | CC47: Notes ⬇️ | CG47: Notes ⬇️
B51: Sets | C51: Reps | D51: Weight
B52: 3 | C52: 8 - 12 | D52: 10 - 15 lbs | E52: Effort Level ➡️ | I52: Effort Level ➡️ | M52: Effort Level ➡️ | Q52: Effort Level ➡️ | U52: Effort Level ➡️ | Y52: Effort Level ➡️ | AC52: Effort Level ➡️ | AG52: Effort Level ➡️ | AK52: Effort Level ➡️ | AO52: Effort Level ➡️ | AS52: Effort Level ➡️ | AW52: Effort Level ➡️ | BA52: Effort Level ➡️ | BE52: Effort Level ➡️ | BI52: Effort Level ➡️ | BM52: Effort Level ➡️ | BQ52: Effort Level ➡️ | BU52: Effort Level ➡️ | BY52: Effort Level ➡️ | CC52: Effort Level ➡️ | CG52: Effort Level ➡️
A54: FALSE | B54: Off-Side (Lopsided) Deadlifts | D54: LINK | E54: Notes ⬇️ | I54: Notes ⬇️ | M54: Notes ⬇️ | Q54: Notes ⬇️ | U54: Notes ⬇️ | Y54: Notes ⬇️ | AC54: Notes ⬇️ | AG54: Notes ⬇️ | AK54: Notes ⬇️ | AO54: Notes ⬇️ | AS54: Notes ⬇️ | AW54: Notes ⬇️ | BA54: Notes ⬇️ | BE54: Notes ⬇️ | BI54: Notes ⬇️ | BM54: Notes ⬇️ | BQ54: Notes ⬇️ | BU54: Notes ⬇️ | BY54: Notes ⬇️ | CC54: Notes ⬇️ | CG54: Notes ⬇️
B58: Sets | C58: Reps | D58: Weight
B59: 3 | C59: 8 - 12 | D59: 20 - 30 lbs | E59: Effort Level ➡️ | I59: Effort Level ➡️ | M59: Effort Level ➡️ | Q59: Effort Level ➡️ | U59: Effort Level ➡️ | Y59: Effort Level ➡️ | AC59: Effort Level ➡️ | AG59: Effort Level ➡️ | AK59: Effort Level ➡️ | AO59: Effort Level ➡️ | AS59: Effort Level ➡️ | AW59: Effort Level ➡️ | BA59: Effort Level ➡️ | BE59: Effort Level ➡️ | BI59: Effort Level ➡️ | BM59: Effort Level ➡️ | BQ59: Effort Level ➡️ | BU59: Effort Level ➡️ | BY59: Effort Level ➡️ | CC59: Effort Level ➡️ | CG59: Effort Level ➡️
A61: FALSE | B61: Banded Hamstring Curls | D61: LINK | E61: Notes ⬇️ | I61: Notes ⬇️ | M61: Notes ⬇️ | Q61: Notes ⬇️ | U61: Notes ⬇️ | Y61: Notes ⬇️ | AC61: Notes ⬇️ | AG61: Notes ⬇️ | AK61: Notes ⬇️ | AO61: Notes ⬇️ | AS61: Notes ⬇️ | AW61: Notes ⬇️ | BA61: Notes ⬇️ | BE61: Notes ⬇️ | BI61: Notes ⬇️ | BM61: Notes ⬇️ | BQ61: Notes ⬇️ | BU61: Notes ⬇️ | BY61: Notes ⬇️ | CC61: Notes ⬇️ | CG61: Notes ⬇️
B65: Sets | C65: Reps | D65: Weight
B66: 3 | C66: 8 - 12 | D66: Bodyweight | E66: Effort Level ➡️ | I66: Effort Level ➡️ | M66: Effort Level ➡️ | Q66: Effort Level ➡️ | U66: Effort Level ➡️ | Y66: Effort Level ➡️ | AC66: Effort Level ➡️ | AG66: Effort Level ➡️ | AK66: Effort Level ➡️ | AO66: Effort Level ➡️ | AS66: Effort Level ➡️ | AW66: Effort Level ➡️ | BA66: Effort Level ➡️ | BE66: Effort Level ➡️ | BI66: Effort Level ➡️ | BM66: Effort Level ➡️ | BQ66: Effort Level ➡️ | BU66: Effort Level ➡️ | BY66: Effort Level ➡️ | CC66: Effort Level ➡️ | CG66: Effort Level ➡️
A68: FALSE | B68: Soleus Raises | D68: LINK | E68: Notes ⬇️ | I68: Notes ⬇️ | M68: Notes ⬇️ | Q68: Notes ⬇️ | U68: Notes ⬇️ | Y68: Notes ⬇️ | AC68: Notes ⬇️ | AG68: Notes ⬇️ | AK68: Notes ⬇️ | AO68: Notes ⬇️ | AS68: Notes ⬇️ | AW68: Notes ⬇️ | BA68: Notes ⬇️ | BE68: Notes ⬇️ | BI68: Notes ⬇️ | BM68: Notes ⬇️ | BQ68: Notes ⬇️ | BU68: Notes ⬇️ | BY68: Notes ⬇️ | CC68: Notes ⬇️ | CG68: Notes ⬇️
B72: Sets | C72: Reps | D72: Weight
B73: 3 | C73: 8 - 12 | D73: 25 - 40 lbs | E73: Effort Level ➡️ | I73: Effort Level ➡️ | M73: Effort Level ➡️ | Q73: Effort Level ➡️ | U73: Effort Level ➡️ | Y73: Effort Level ➡️ | AC73: Effort Level ➡️ | AG73: Effort Level ➡️ | AK73: Effort Level ➡️ | AO73: Effort Level ➡️ | AS73: Effort Level ➡️ | AW73: Effort Level ➡️ | BA73: Effort Level ➡️ | BE73: Effort Level ➡️ | BI73: Effort Level ➡️ | BM73: Effort Level ➡️ | BQ73: Effort Level ➡️ | BU73: Effort Level ➡️ | BY73: Effort Level ➡️ | CC73: Effort Level ➡️ | CG73: Effort Level ➡️
A75: FALSE | B75: Elevated Depth Squat | D75: LINK | E75: Notes ⬇️ | I75: Notes ⬇️ | M75: Notes ⬇️ | Q75: Notes ⬇️ | U75: Notes ⬇️ | Y75: Notes ⬇️ | AC75: Notes ⬇️ | AG75: Notes ⬇️ | AK75: Notes ⬇️ | AO75: Notes ⬇️ | AS75: Notes ⬇️ | AW75: Notes ⬇️ | BA75: Notes ⬇️ | BE75: Notes ⬇️ | BI75: Notes ⬇️ | BM75: Notes ⬇️ | BQ75: Notes ⬇️ | BU75: Notes ⬇️ | BY75: Notes ⬇️ | CC75: Notes ⬇️ | CG75: Notes ⬇️
B79: Sets | C79: Reps | D79: Weight
B80: 3 | C80: 8 - 12 | D80: 25 - 45 lbs | E80: Effort Level ➡️ | I80: Effort Level ➡️ | M80: Effort Level ➡️ | Q80: Effort Level ➡️ | U80: Effort Level ➡️ | Y80: Effort Level ➡️ | AC80: Effort Level ➡️ | AG80: Effort Level ➡️ | AK80: Effort Level ➡️ | AO80: Effort Level ➡️ | AS80: Effort Level ➡️ | AW80: Effort Level ➡️ | BA80: Effort Level ➡️ | BE80: Effort Level ➡️ | BI80: Effort Level ➡️ | BM80: Effort Level ➡️ | BQ80: Effort Level ➡️ | BU80: Effort Level ➡️ | BY80: Effort Level ➡️ | CC80: Effort Level ➡️ | CG80: Effort Level ➡️
A82: Needs Work | B82: Strength Workout 2 | D82: Warm-Up VIDEO | E82: Date | F82: Workout 1 Data | I82: Date | J82: Workout 2 Data | M82: Date | N82: Workout 3 Data | Q82: Date | R82: Workout 4 Data | U82: Date | V82: Workout 5 Data | Y82: Date | Z82: Workout 6 Data | AC82: Date | AD82: Workout 7 Data | AG82: Date | AH82: Workout 8 Data | AK82: Date | AL82: Workout 9 Data | AO82: Date | AP82: Workout 10 Data | AS82: Date | AT82: Workout 11 Data | AW82: Date | AX82: Workout 12 Data | BA82: Date | BB82: Workout 13 Data | BE82: Date | BF82: Workout 14 Data | BI82: Date | BJ82: Workout 15 Data | BM82: Date | BN82: Workout 17 Data | BQ82: Date | BR82: Workout 18 Data | BU82: Date | BV82: Workout 19 Data | BY82: Date | BZ82: Workout 20 Data | CC82: Date | CD82: Workout 21 Data | CG82: Date | CH82: Workout 22 Data
E84: 46023 | F84: Weight | G84: Reps | I84: 46023 | J84: Weight | K84: Reps | M84: 46023 | N84: Weight | O84: Reps | Q84: 46023 | R84: Weight | S84: Reps | U84: 46023 | V84: Weight | W84: Reps | Y84: 46023 | Z84: Weight | AA84: Reps | AC84: 46023 | AD84: Weight | AE84: Reps | AG84: 46023 | AH84: Weight | AI84: Reps | AK84: 46023 | AL84: Weight | AM84: Reps | AO84: 46023 | AP84: Weight | AQ84: Reps | AS84: 46023 | AT84: Weight | AU84: Reps | AW84: 46023 | AX84: Weight | AY84: Reps | BA84: 46023 | BB84: Weight | BC84: Reps | BE84: 46023 | BF84: Weight | BG84: Reps | BI84: 46023 | BJ84: Weight | BK84: Reps | BM84: 46023 | BN84: Weight | BO84: Reps | BQ84: 46023 | BR84: Weight | BS84: Reps | BU84: 46023 | BV84: Weight | BW84: Reps | BY84: 46023 | BZ84: Weight | CA84: Reps | CC84: 46023 | CD84: Weight | CE84: Reps | CG84: 46023 | CH84: Weight | CI84: Reps
A86: FALSE | B86: Ab Roller | D86: LINK | E86: Notes ⬇️ | I86: Notes ⬇️ | M86: Notes ⬇️ | Q86: Notes ⬇️ | U86: Notes ⬇️ | Y86: Notes ⬇️ | AC86: Notes ⬇️ | AG86: Notes ⬇️ | AK86: Notes ⬇️ | AO86: Notes ⬇️ | AS86: Notes ⬇️ | AW86: Notes ⬇️ | BA86: Notes ⬇️ | BE86: Notes ⬇️ | BI86: Notes ⬇️ | BM86: Notes ⬇️ | BQ86: Notes ⬇️ | BU86: Notes ⬇️ | BY86: Notes ⬇️ | CC86: Notes ⬇️ | CG86: Notes ⬇️
B90: Sets | C90: Reps | D90: Weight
B91: 3 | C91: 8 - 12 | D91: Bodyweight | E91: Effort Level ➡️ | I91: Effort Level ➡️ | M91: Effort Level ➡️ | Q91: Effort Level ➡️ | U91: Effort Level ➡️ | Y91: Effort Level ➡️ | AC91: Effort Level ➡️ | AG91: Effort Level ➡️ | AK91: Effort Level ➡️ | AO91: Effort Level ➡️ | AS91: Effort Level ➡️ | AW91: Effort Level ➡️ | BA91: Effort Level ➡️ | BE91: Effort Level ➡️ | BI91: Effort Level ➡️ | BM91: Effort Level ➡️ | BQ91: Effort Level ➡️ | BU91: Effort Level ➡️ | BY91: Effort Level ➡️ | CC91: Effort Level ➡️ | CG91: Effort Level ➡️
...

Sheet January 
A1: STRAVA | B1: J A N U A R Y | H1: MONTH GOAL➡️ | J1: This month we will practice heavier speed work for 5k/10k and hills specifcially for Boston! Stay on top of the little things and let me now if anything hurts or is too hard ASAP!! This will build our base for the next few months!
B2: Warm-Up Distance➡️ | C2: 1.5 mile | D2: Warm-Up & Cool Down Routine | F2: Rolling Routine
B3: Cool Down Distance➡️ | C3: 1.5 mile | F3: Stretching Routine
B4: Monday | D4: Tuesday | F4: Wednesday | H4: Thursday | J4: Friday | L4: Saturday | N4: Sunday | P4: Planned Mileage | Q4: Actual Mileage
B5: EASY RUN | D5: HARD WORKOUT & STRENGTH | F5: EASY RUN | H5: HARD WORKOUT & STRENGTH | J5: REST | L5: LONG RUN | N5: REST OR EASY RUN
A6: BUILD WEEK | B6: 46027 | D6: 46028 | F6: 46029 | H6: 46030 | J6: 46031 | L6: 46032 | N6: 46033 | P6: =SUM(B7,D7,F7,H7,J7,L7,N7) -> 40
B7: 5 | C7: SPLITS | D7: 8 | E7: SPLITS | F7: 5 | G7: SPLITS | H7: 5 | I7: SPLITS | J7: 0 | K7: SPLITS | L7: 12 | M7: SPLITS | N7: 5 | O7: SPLITS
B8: Easy Run Start around 10:00 and work down to 9:00 IF IT FEELS EASY 4-6 miles | C8: 6 miles | D8: 10x800m w/ 90s walk rest btwn 1st 4: 3:40-3:30 2nd 4: 3:30-3:20 3rd 2: 3:20-3:10 | F8: Easy Run Start around 10:00 and work down to 9:00 IF IT FEELS EASY 4-6 miles | H8: HILLS 3 miles of 60-90s UP @ 90% w/ walk/jog back down TREADMILL (3-4% incline): 60-90s UP @ 6:50-6:30 pace w/ 90s standing rest btwn | J8: Day Off | L8: Easy Long Run IF YOU FEEL GOOD: Close last 2-3 miles sub 8:00 | N8: Easy Run Start around 10:00 and work down to 9:00 IF IT FEELS EASY 4-6 miles
B9: AVG HR | C9: AVG PACE | D9: AVG HR | E9: AVG PACE | F9: AVG HR | G9: AVG PACE | H9: AVG HR | I9: AVG PACE | J9: AVG HR | K9: AVG PACE | L9: AVG HR | M9: AVG PACE | N9: AVG HR | O9: AVG PACE
C10: 0.37430556
A11: Focus More on Strength | B11: TODAY'S NOTES | D11: TODAY'S NOTES | F11: TODAY'S NOTES | H11: TODAY'S NOTES | J11: TODAY'S NOTES | L11: TODAY'S NOTES | N11: TODAY'S NOTES | P11: WEEK THOUGHTS
B13: Roll/ Stretch | C13: TRUE | D13: Roll/ Stretch | E13: FALSE | F13: Roll/ Stretch | G13: FALSE | H13: Roll/ Stretch | I13: FALSE | J13: Roll/ Stretch | K13: FALSE | L13: Roll/ Stretch | M13: FALSE | N13: Roll/ Stretch | O13: FALSE | P13: =COUNTIF(B13:O13,True)/COUNTA(B13:O13)%/50 -> 0.14285714 | Q13: Recovery Score
B14: Refuel/ Rehydrate | C14: TRUE | D14: Refuel/ Rehydrate | E14: FALSE | F14: Refuel/ Rehydrate | G14: FALSE | H14: Refuel/ Rehydrate | I14: FALSE | J14: Refuel/ Rehydrate | K14: FALSE | L14: Refuel/ Rehydrate | M14: FALSE | N14: Refuel/ Rehydrate | O14: FALSE | P14: =COUNTIF(B14:O14,True)/COUNTA(B14:O14)%/50 -> 0.14285714
B15: Strength Work | C15: Yes | D15: Strength Work | F15: Strength Work | H15: Strength Work | J15: Strength Work | L15: Strength Work | N15: Strength Work | P15: =COUNTIF(B15:O15,"Yes") -> 1 | Q15: Goal: 2-3
B16: Effort Level 1-10 | C16: 3 | D16: Effort Level 1-10 | F16: Effort Level 1-10 | H16: Effort Level 1-10 | J16: Effort Level 1-10 | L16: Effort Level 1-10 | N16: Effort Level 1-10 | P16: =SUM(C16,E16,G16,I16,K16,M16,O16)/7 -> 0.42857143 | Q16: Avg. Goal: 3-6
A18: BUILD WEEK | B18: 46034 | D18: 46035 | F18: 46036 | H18: 46037 | J18: 46038 | L18: 46039 | N18: 46040 | P18: Planned Mileage | Q18: Actual Mileage
B19: 5 | C19: SPLITS | D19: 8 | E19: SPLITS | F19: 5 | G19: SPLITS | H19: 4 | I19: SPLITS | J19: 0 | K19: SPLITS | L19: 13 | M19: SPLITS | N19: 5 | O19: SPLITS
B20: Easy Run Start around 10:00 and work down to 9:00 IF IT FEELS EASY 4-6 miles | D20: 5 miles of 2 min ON and 2 min EASY ON Pace: 6:40-6:20 | F20: Easy Run Start around 10:00 and work down to 9:00 IF IT FEELS EASY 4-6 miles | H20: 8x400m @ 1:30-1:25 w/ 2 min walk rest btwn FOCUS ON SPEED AND PLENTY OF REST | J20: Day Off | L20: Easy Long Run IF YOU FEEL GOOD: Close last 2-3 miles sub 8:00 | N20: Easy Run Start around 10:00 and work down to 9:00 IF IT FEELS EASY 4-6 miles | P20: =SUM(B19,D19,F19,H19,J19,L19,N19) -> 40
B21: AVG HR | C21: AVG PACE | D21: AVG HR | E21: AVG PACE | F21: AVG HR | G21: AVG PACE | H21: AVG HR | I21: AVG PACE | J21: AVG HR | K21: AVG PACE | L21: AVG HR | M21: AVG PACE | N21: AVG HR | O21: AVG PACE
A23: Focus More on Strength | B23: TODAY'S NOTES | D23: TODAY'S NOTES | F23: TODAY'S NOTES | H23: TODAY'S NOTES | J23: TODAY'S NOTES | L23: TODAY'S NOTES | N23: TODAY'S NOTES | P23: WEEK THOUGHTS
B25: Roll/ Stretch | C25: FALSE | D25: Roll/ Stretch | E25: FALSE | F25: Roll/ Stretch | G25: FALSE | H25: Roll/ Stretch | I25: FALSE | J25: Roll/ Stretch | K25: FALSE | L25: Roll/ Stretch | M25: FALSE | N25: Roll/ Stretch | O25: FALSE | P25: =COUNTIF(B25:O25,True)/COUNTA(B25:O25)%/50 -> 0 | Q25: Recovery Score
B26: Refuel/ Rehydrate | C26: FALSE | D26: Refuel/ Rehydrate | E26: FALSE | F26: Refuel/ Rehydrate | G26: FALSE | H26: Refuel/ Rehydrate | I26: FALSE | J26: Refuel/ Rehydrate | K26: FALSE | L26: Refuel/ Rehydrate | M26: FALSE | N26: Refuel/ Rehydrate | O26: FALSE | P26: =COUNTIF(B26:O26,True)/COUNTA(B26:O26)%/50 -> 0
B27: Strength Work | D27: Strength Work | F27: Strength Work | H27: Strength Work | J27: Strength Work | L27: Strength Work | N27: Strength Work | P27: =COUNTIF(B27:O27,"Yes") -> 0 | Q27: Goal: 2-3
B28: Effort Level 1-10 | D28: Effort Level 1-10 | F28: Effort Level 1-10 | H28: Effort Level 1-10 | J28: Effort Level 1-10 | L28: Effort Level 1-10 | N28: Effort Level 1-10 | P28: =SUM(C28,E28,G28,I28,K28,M28,O28)/7 -> 0 | Q28: Avg. Goal: 3-6
A30: REST WEEK | B30: 46041 | D30: 46042 | F30: 46043 | H30: 46044 | J30: 46045 | L30: 46046 | N30: 46047 | P30: Planned Mileage | Q30: Actual Mileage
B31: 3 | C31: SPLITS | D31: 8 | E31: SPLITS | F31: 3 | G31: SPLITS | H31: 5 | I31: SPLITS | J31: 0 | K31: SPLITS | L31: 10 | M31: SPLITS | N31: 3 | O31: SPLITS
B32: Easy Run Start around 10:00 and work down to 9:00 IF IT FEELS EASY | D32: 5x1 mile @ 7:10, 7:00, 6:50, 6:40, 6:30 w/ 2-3 min walk/jog btwn | F32: Easy Run Start around 10:00 and work down to 9:00 IF IT FEELS EASY | H32: HILLS 3 miles of 60-90s UP @ 90% w/ walk/jog back down TREADMILL (3-4% incline): 60-90s UP @ 6:50-6:30 pace w/ 90s standing rest btwn | J32: Day Off | L32: SUPER EASY LONG RUN | N32: Easy Run Start around 10:00 and work down to 9:00 IF IT FEELS EASY | P32: =SUM(B31,D31,F31,H31,J31,L31,N31) -> 32
B33: AVG HR | C33: AVG PACE | D33: AVG HR | E33: AVG PACE | F33: AVG HR | G33: AVG PACE | H33: AVG HR | I33: AVG PACE | J33: AVG HR | K33: AVG PACE | L33: AVG HR | M33: AVG PACE | N33: AVG HR | O33: AVG PACE
A35: Don't Push/ Strict Paces | B35: TODAY'S NOTES | D35: TODAY'S NOTES | F35: TODAY'S NOTES | H35: TODAY'S NOTES | J35: TODAY'S NOTES | L35: TODAY'S NOTES | N35: TODAY'S NOTES | P35: WEEK THOUGHTS
B37: Roll/ Stretch | C37: FALSE | D37: Roll/ Stretch | E37: FALSE | F37: Roll/ Stretch | G37: FALSE | H37: Roll/ Stretch | I37: FALSE | J37: Roll/ Stretch | K37: FALSE | L37: Roll/ Stretch | M37: FALSE | N37: Roll/ Stretch | O37: FALSE | P37: =COUNTIF(B37:O37,True)/COUNTA(B37:O37)%/50 -> 0 | Q37: Recovery Score
B38: Refuel/ Rehydrate | C38: FALSE | D38: Refuel/ Rehydrate | E38: FALSE | F38: Refuel/ Rehydrate | G38: FALSE | H38: Refuel/ Rehydrate | I38: FALSE | J38: Refuel/ Rehydrate | K38: FALSE | L38: Refuel/ Rehydrate | M38: FALSE | N38: Refuel/ Rehydrate | O38: FALSE | P38: =COUNTIF(B38:O38,True)/COUNTA(B38:O38)%/50 -> 0
B39: Strength Work | D39: Strength Work | F39: Strength Work | H39: Strength Work | J39: Strength Work | L39: Strength Work | N39: Strength Work | P39: =COUNTIF(B39:O39,"Yes") -> 0 | Q39: Goal: 2-3
B40: Effort Level 1-10 | D40: Effort Level 1-10 | F40: Effort Level 1-10 | H40: Effort Level 1-10 | J40: Effort Level 1-10 | L40: Effort Level 1-10 | N40: Effort Level 1-10 | P40: =SUM(C40,E40,G40,I40,K40,M40,O40)/7 -> 0 | Q40: Avg. Goal: 3-6
A42: PUSH WEEK | B42: 46048 | D42: 46049 | F42: 46050 | H42: 46051 | J42: 46052 | L42: 46053 | N42: 46054 | P42: Planned Mileage | Q42: Actual Mileage
B43: 5 | C43: SPLITS | D43: 9 | E43: SPLITS | F43: 5 | G43: SPLITS | H43: 4 | I43: SPLITS | J43: 0 | K43: SPLITS | L43: 15 | M43: SPLITS | N43: 5 | O43: SPLITS
B44: Easy Run Start around 10:00 and work down to 9:00 IF IT FEELS EASY 4-6 miles | D44: 6 miles of 3 min ON and 2 min EASY ON Pace: 6:40-6:20 COMPARE TO 2 WEEKS AGO | F44: Easy Run Start around 10:00 and work down to 9:00 IF IT FEELS EASY 4-6 miles | H44: 10-12x400m @ 1:30-1:25 w/ 2 min walk rest btwn COMPARE TO 2 WEEKS AGO | J44: Day Off | L44: Easy Long Run IF YOU FEEL GOOD: Close last 2-3 miles sub 8:00 | N44: Easy Run Start around 10:00 and work down to 9:00 IF IT FEELS EASY 4-6 miles | P44: =SUM(B43,D43,F43,H43,J43,L43,N43) -> 43
B45: AVG HR | C45: AVG PACE | D45: AVG HR | E45: AVG PACE | F45: AVG HR | G45: AVG PACE | H45: AVG HR | I45: AVG PACE | J45: AVG HR | K45: AVG PACE | L45: AVG HR | M45: AVG PACE | N45: AVG HR | O45: AVG PACE
A47: Stay on Top of the Little Things / Be Ready to Push | B47: TODAY'S NOTES | D47: TODAY'S NOTES | F47: TODAY'S NOTES | H47: TODAY'S NOTES | J47: TODAY'S NOTES | L47: TODAY'S NOTES | N47: TODAY'S NOTES | P47: WEEK THOUGHTS
B49: Roll/ Stretch | C49: FALSE | D49: Roll/ Stretch | E49: FALSE | F49: Roll/ Stretch | G49: FALSE | H49: Roll/ Stretch | I49: FALSE | J49: Roll/ Stretch | K49: FALSE | L49: Roll/ Stretch | M49: FALSE | N49: Roll/ Stretch | O49: FALSE | P49: =COUNTIF(B49:O49,True)/COUNTA(B49:O49)%/50 -> 0 | Q49: Recovery Score
B50: Refuel/ Rehydrate | C50: FALSE | D50: Refuel/ Rehydrate | E50: FALSE | F50: Refuel/ Rehydrate | G50: FALSE | H50: Refuel/ Rehydrate | I50: FALSE | J50: Refuel/ Rehydrate | K50: FALSE | L50: Refuel/ Rehydrate | M50: FALSE | N50: Refuel/ Rehydrate | O50: FALSE | P50: =COUNTIF(B50:O50,True)/COUNTA(B50:O50)%/50 -> 0
...

Sheet February 
A1: ='January '!A1 -> STRAVA | B1: F E B R U A R Y | H1: MONTH GOAL➡️ | J1: This month we will work on hills a bit and continue to build speed! Stay on top of strength and recovery so we can have a big month before Tokyo!
B2: Warm-Up Distance➡️ | C2: ='January '!C2 -> 1.5 mile | D2: Warm-Up & Cool Down Routine | F2: Rolling Routine
B3: Cool Down Distance➡️ | C3: ='January '!C3 -> 1.5 mile | F3: Stretching Routine
B4: Monday | D4: Tuesday | F4: Wednesday | H4: Thursday | J4: Friday | L4: Saturday | N4: Sunday | P4: Planned Mileage | Q4: Actual Mileage
B5: ='January '!B5 -> EASY RUN | D5: ='January '!D5 -> HARD WORKOUT & STRENGTH | F5: ='January '!F5 -> EASY RUN | H5: ='January '!H5 -> HARD WORKOUT & STRENGTH | J5: ='January '!J5 -> REST | L5: ='January '!L5 -> LONG RUN | N5: ='January '!N5 -> REST OR EASY RUN
A6: BUILD WEEK | B6: 46055 | D6: 46056 | F6: 46057 | H6: 46058 | J6: 46059 | L6: 46060 | N6: 46061 | P6: =SUM(B7,D7,F7,H7,J7,L7,N7) -> 45
B7: 5 | C7: SPLITS | D7: 9 | E7: SPLITS | F7: 5 | G7: SPLITS | H7: 5 | I7: SPLITS | J7: 0 | K7: SPLITS | L7: 16 | M7: SPLITS | N7: 5 | O7: SPLITS
B8: Easy Run Start around 10:00 and work down to 9:00 IF IT FEELS EASY 4-6 miles | D8: 6x1 mile @ 7:10, 7:00, 6:50, 6:50-6:40, 6:40, 6:30 w/ 2-3 min walk/jog btwn COMPARE TO LAST MONTH | F8: Easy Run Start around 10:00 and work down to 9:00 IF IT FEELS EASY 4-6 miles | H8: HILLS 3 miles of 60-90s UP @ 90% w/ walk/jog back down TREADMILL (3-4% incline): 60-90s UP @ 6:50-6:30 pace w/ 90s standing rest btwn | J8: Day Off | L8: Easy Long Run 15-17 MILES IF YOU FEEL GOOD: Close last 2-5 miles sub 8:00 | N8: Easy Run Start around 10:00 and work down to 9:00 IF IT FEELS EASY 4-6 miles
B9: AVG HR | C9: AVG PACE | D9: AVG HR | E9: AVG PACE | F9: AVG HR | G9: AVG PACE | H9: AVG HR | I9: AVG PACE | J9: AVG HR | K9: AVG PACE | L9: AVG HR | M9: AVG PACE | N9: AVG HR | O9: AVG PACE
A11: Focus More on Strength | B11: TODAY'S NOTES | D11: TODAY'S NOTES | F11: TODAY'S NOTES | H11: TODAY'S NOTES | J11: TODAY'S NOTES | L11: TODAY'S NOTES | N11: TODAY'S NOTES | P11: WEEK THOUGHTS
B13: Roll/ Stretch | C13: FALSE | D13: Roll/ Stretch | E13: FALSE | F13: Roll/ Stretch | G13: FALSE | H13: Roll/ Stretch | I13: FALSE | J13: Roll/ Stretch | K13: FALSE | L13: Roll/ Stretch | M13: FALSE | N13: Roll/ Stretch | O13: FALSE | P13: =COUNTIF(B13:O13,True)/COUNTA(B13:O13)%/50 -> 0 | Q13: Recovery Score
B14: Refuel/ Rehydrate | C14: FALSE | D14: Refuel/ Rehydrate | E14: FALSE | F14: Refuel/ Rehydrate | G14: FALSE | H14: Refuel/ Rehydrate | I14: FALSE | J14: Refuel/ Rehydrate | K14: FALSE | L14: Refuel/ Rehydrate | M14: FALSE | N14: Refuel/ Rehydrate | O14: FALSE | P14: =COUNTIF(B14:O14,True)/COUNTA(B14:O14)%/50 -> 0
B15: Strength Work | D15: Strength Work | F15: Strength Work | H15: Strength Work | J15: Strength Work | L15: Strength Work | N15: Strength Work | P15: =COUNTIF(B15:O15,"Yes") -> 0 | Q15: Goal: 2-3
B16: Effort Level 1-10 | D16: Effort Level 1-10 | F16: Effort Level 1-10 | H16: Effort Level 1-10 | J16: Effort Level 1-10 | L16: Effort Level 1-10 | N16: Effort Level 1-10 | P16: =SUM(C16,E16,G16,I16,K16,M16,O16)/7 -> 0 | Q16: Avg. Goal: 3-6
A18: BUILD WEEK | B18: 46062 | D18: 46063 | F18: 46064 | H18: 46065 | J18: 46066 | L18: 46067 | N18: 46068 | P18: Planned Mileage | Q18: Actual Mileage
B19: 5 | C19: SPLITS | D19: 10 | E19: SPLITS | F19: 5 | G19: SPLITS | H19: 5 | I19: SPLITS | J19: 0 | K19: SPLITS | L19: 17 | M19: SPLITS | N19: 5 | O19: SPLITS
B20: Easy Run Start around 10:00 and work down to 9:00 IF IT FEELS EASY 4-6 miles | D20: 3x2 miles w/ 800m jog rest btwn Reps: 7:30-7:20 7:20-7:10 7:10-7:00 | F20: Easy Run Start around 10:00 and work down to 9:00 IF IT FEELS EASY 4-6 miles | H20: HILLS 3 miles of 60-90s UP @ 90% w/ walk/jog back down TREADMILL (3-4% incline): 60-90s UP @ 6:50-6:30 pace w/ 90s standing rest btwn | J20: Day Off | L20: Easy Long Run 16-18 MILES IF YOU FEEL GOOD: Close last 2-5 miles sub 8:00 | N20: Easy Run Start around 10:00 and work down to 9:00 IF IT FEELS EASY 4-6 miles | P20: =SUM(B19,D19,F19,H19,J19,L19,N19) -> 47
B21: AVG HR | C21: AVG PACE | D21: AVG HR | E21: AVG PACE | F21: AVG HR | G21: AVG PACE | H21: AVG HR | I21: AVG PACE | J21: AVG HR | K21: AVG PACE | L21: AVG HR | M21: AVG PACE | N21: AVG HR | O21: AVG PACE
A23: Focus More on Strength | B23: TODAY'S NOTES | D23: TODAY'S NOTES | F23: TODAY'S NOTES | H23: TODAY'S NOTES | J23: TODAY'S NOTES | L23: TODAY'S NOTES | N23: TODAY'S NOTES | P23: WEEK THOUGHTS
B25: Roll/ Stretch | C25: FALSE | D25: Roll/ Stretch | E25: FALSE | F25: Roll/ Stretch | G25: FALSE | H25: Roll/ Stretch | I25: FALSE | J25: Roll/ Stretch | K25: FALSE | L25: Roll/ Stretch | M25: FALSE | N25: Roll/ Stretch | O25: FALSE | P25: =COUNTIF(B25:O25,True)/COUNTA(B25:O25)%/50 -> 0 | Q25: Recovery Score
B26: Refuel/ Rehydrate | C26: FALSE | D26: Refuel/ Rehydrate | E26: FALSE | F26: Refuel/ Rehydrate | G26: FALSE | H26: Refuel/ Rehydrate | I26: FALSE | J26: Refuel/ Rehydrate | K26: FALSE | L26: Refuel/ Rehydrate | M26: FALSE | N26: Refuel/ Rehydrate | O26: FALSE | P26: =COUNTIF(B26:O26,True)/COUNTA(B26:O26)%/50 -> 0
B27: Strength Work | D27: Strength Work | F27: Strength Work | H27: Strength Work | J27: Strength Work | L27: Strength Work | N27: Strength Work | P27: =COUNTIF(B27:O27,"Yes") -> 0 | Q27: Goal: 2-3
B28: Effort Level 1-10 | D28: Effort Level 1-10 | F28: Effort Level 1-10 | H28: Effort Level 1-10 | J28: Effort Level 1-10 | L28: Effort Level 1-10 | N28: Effort Level 1-10 | P28: =SUM(C28,E28,G28,I28,K28,M28,O28)/7 -> 0 | Q28: Avg. Goal: 3-6
A30: REST WEEK | B30: 46069 | D30: 46070 | F30: 46071 | H30: 46072 | J30: 46073 | L30: 46074 | N30: 46075 | P30: Planned Mileage | Q30: Actual Mileage
B31: 3 | C31: SPLITS | D31: 10 | E31: SPLITS | F31: 3 | G31: SPLITS | H31: 5 | I31: SPLITS | J31: 0 | K31: SPLITS | L31: 12 | M31: SPLITS | N31: 3 | O31: SPLITS
B32: Easy Run Start around 10:00 and work down to 9:00 IF IT FEELS EASY | D32: 5 miles @ 7:40-7:30 CONTROLLED; 1 mile EASY; 1 mile @ sub 7:10 PUSHING | F32: Easy Run Start around 10:00 and work down to 9:00 IF IT FEELS EASY | H32: HILLS 3 miles of 60-90s UP @ 90% w/ walk/jog back down TREADMILL (3-4% incline): 60-90s UP @ 6:50-6:30 pace w/ 90s standing rest btwn | J32: Day Off | L32: SUPER EASY LONG RUN | N32: Easy Run Start around 10:00 and work down to 9:00 IF IT FEELS EASY | P32: =SUM(B31,D31,F31,H31,J31,L31,N31) -> 36
B33: AVG HR | C33: AVG PACE | D33: AVG HR | E33: AVG PACE | F33: AVG HR | G33: AVG PACE | H33: AVG HR | I33: AVG PACE | J33: AVG HR | K33: AVG PACE | L33: AVG HR | M33: AVG PACE | N33: AVG HR | O33: AVG PACE
A35: Focus HEAVILY on Rolling/ Stretching/ Recovery | B35: TODAY'S NOTES | D35: TODAY'S NOTES | F35: TODAY'S NOTES | H35: TODAY'S NOTES | J35: TODAY'S NOTES | L35: TODAY'S NOTES | N35: TODAY'S NOTES | P35: WEEK THOUGHTS
B37: Roll/ Stretch | C37: FALSE | D37: Roll/ Stretch | E37: FALSE | F37: Roll/ Stretch | G37: FALSE | H37: Roll/ Stretch | I37: FALSE | J37: Roll/ Stretch | K37: FALSE | L37: Roll/ Stretch | M37: FALSE | N37: Roll/ Stretch | O37: FALSE | P37: =COUNTIF(B37:O37,True)/COUNTA(B37:O37)%/50 -> 0 | Q37: Recovery Score
B38: Refuel/ Rehydrate | C38: FALSE | D38: Refuel/ Rehydrate | E38: FALSE | F38: Refuel/ Rehydrate | G38: FALSE | H38: Refuel/ Rehydrate | I38: FALSE | J38: Refuel/ Rehydrate | K38: FALSE | L38: Refuel/ Rehydrate | M38: FALSE | N38: Refuel/ Rehydrate | O38: FALSE | P38: =COUNTIF(B38:O38,True)/COUNTA(B38:O38)%/50 -> 0
B39: Strength Work | D39: Strength Work | F39: Strength Work | H39: Strength Work | J39: Strength Work | L39: Strength Work | N39: Strength Work | P39: =COUNTIF(B39:O39,"Yes") -> 0 | Q39: Goal: 2-3
B40: Effort Level 1-10 | D40: Effort Level 1-10 | F40: Effort Level 1-10 | H40: Effort Level 1-10 | J40: Effort Level 1-10 | L40: Effort Level 1-10 | N40: Effort Level 1-10 | P40: =SUM(C40,E40,G40,I40,K40,M40,O40)/7 -> 0 | Q40: Avg. Goal: 3-6
A42: BUILD WEEK | B42: 46076 | D42: 46077 | F42: 46078 | H42: 46079 | J42: 46080 | L42: 46081 | N42: 46082 | P42: Planned Mileage | Q42: Actual Mileage
B43: 5 | C43: SPLITS | D43: 16 | E43: SPLITS | F43: 5 | G43: SPLITS | H43: 0 | I43: SPLITS | J43: 5 | K43: SPLITS | L43: 8 | M43: SPLITS | N43: 5 | O43: SPLITS
B44: Easy Run Start around 10:00 and work down to 9:00 IF IT FEELS EASY 4-6 miles | D44: LONG RUN WORKOUT 3 miles easy; 10x1 mile @ 7:25-7:15 w/ 2:30 jog rest btwn; 1-2 miles easy PRACTICE FUELING | F44: Easy Run Start around 10:00 and work down to 9:00 IF IT FEELS EASY 4-6 miles | H44: Day Off | J44: Easy Run Start around 10:00 and work down to 9:00 IF IT FEELS EASY 4-6 miles | L44: 5 miles of 2 min ON and 2 min EASY ON Pace: 7:30-6:45 LIGHT WORKOUT WORK DOWN GENTLY OR EASY RUN 3-5 MILES | N44: Easy Run Start around 10:00 and work down to 9:00 IF IT FEELS EASY 4-6 miles | P44: =SUM(B43,D43,F43,H43,J43,L43,N43) -> 44
B45: AVG HR | C45: AVG PACE | D45: AVG HR | E45: AVG PACE | F45: AVG HR | G45: AVG PACE | H45: AVG HR | I45: AVG PACE | J45: AVG HR | K45: AVG PACE | L45: AVG HR | M45: AVG PACE | N45: AVG HR | O45: AVG PACE
A47: Prep/Fuel Like Race Week | B47: TODAY'S NOTES | D47: TODAY'S NOTES | F47: TODAY'S NOTES | H47: TODAY'S NOTES | J47: TODAY'S NOTES | L47: TODAY'S NOTES | N47: TODAY'S NOTES | P47: WEEK THOUGHTS
B49: Roll/ Stretch | C49: FALSE | D49: Roll/ Stretch | E49: FALSE | F49: Roll/ Stretch | G49: FALSE | H49: Roll/ Stretch | I49: FALSE | J49: Roll/ Stretch | K49: FALSE | L49: Roll/ Stretch | M49: FALSE | N49: Roll/ Stretch | O49: FALSE | P49: =COUNTIF(B49:O49,True)/COUNTA(B49:O49)%/50 -> 0 | Q49: Recovery Score
B50: Refuel/ Rehydrate | C50: FALSE | D50: Refuel/ Rehydrate | E50: FALSE | F50: Refuel/ Rehydrate | G50: FALSE | H50: Refuel/ Rehydrate | I50: FALSE | J50: Refuel/ Rehydrate | K50: FALSE | L50: Refuel/ Rehydrate | M50: FALSE | N50: Refuel/ Rehydrate | O50: FALSE | P50: =COUNTIF(B50:O50,True)/COUNTA(B50:O50)%/50 -> 0
B51: Strength Work | D51: Strength Work | F51: Strength Work | H51: Strength Work | J51: Strength Work | L51: Strength Work | N51: Strength Work | P51: =COUNTIF(B51:O51,"Yes") -> 0 | Q51: Goal: 2-3
...

Sheet March 
A1: ='February '!A1 -> STRAVA | B1: M A R C H | H1: MONTH GOAL➡️ | J1: Let's keep building fitness! I'll avoid harder workouts in Japan so you can enjoy the vacation! If we can get in hard workouts great! If not then don't stress it!
B2: Warm-Up Distance➡️ | C2: ='February '!C2 -> 1.5 mile | D2: Warm-Up & Cool Down Routine | F2: Rolling Routine
B3: Cool Down Distance➡️ | C3: ='February '!C3 -> 1.5 mile | F3: Stretching Routine
B4: Monday | D4: Tuesday | F4: Wednesday | H4: Thursday | J4: Friday | L4: Saturday | N4: Sunday | P4: Planned Mileage | Q4: Actual Mileage
B5: ='February '!B5 -> EASY RUN | D5: ='February '!D5 -> HARD WORKOUT & STRENGTH | F5: ='February '!F5 -> EASY RUN | H5: ='February '!H5 -> HARD WORKOUT & STRENGTH | J5: ='February '!J5 -> REST | L5: ='February '!L5 -> LONG RUN | N5: ='February '!N5 -> REST OR EASY RUN
A6: BUILD WEEK | B6: 46083 | D6: 46084 | F6: 46085 | H6: 46086 | J6: 46087 | L6: 46088 | N6: 46089 | P6: =SUM(B7,D7,F7,H7,J7,L7,N7) -> 46
B7: 5 | C7: SPLITS | D7: 8 | E7: SPLITS | F7: 5 | G7: SPLITS | H7: 5 | I7: SPLITS | J7: 0 | K7: SPLITS | L7: 18 | M7: SPLITS | N7: 5 | O7: SPLITS
B8: Easy Run Start around 10:00 and work down to 9:00 IF IT FEELS EASY 4-6 miles | D8: 10x800m @ 3:20-3:10 w/ 1:30-2:00 walk/jog rest btwn | F8: Easy Run Start around 10:00 and work down to 9:00 IF IT FEELS EASY 4-6 miles | H8: HILLS 3 miles of 60-90s UP @ 90% w/ walk/jog back down TREADMILL (3-4% incline): 60-90s UP @ 6:50-6:30 pace w/ 90s standing rest btwn | J8: Day Off | L8: STEADY STATE LONG RUN 4 miles easy; 10 miles @ 8:20-7:50; 4 miles easy PRACTICE FUELING | N8: Easy Run Start around 10:00 and work down to 9:00 IF IT FEELS EASY 4-6 miles
B9: AVG HR | C9: AVG PACE | D9: AVG HR | E9: AVG PACE | F9: AVG HR | G9: AVG PACE | H9: AVG HR | I9: AVG PACE | J9: AVG HR | K9: AVG PACE | L9: AVG HR | M9: AVG PACE | N9: AVG HR | O9: AVG PACE
A11: Focus More on Strength | B11: TODAY'S NOTES | D11: TODAY'S NOTES | F11: TODAY'S NOTES | H11: TODAY'S NOTES | J11: TODAY'S NOTES | L11: TODAY'S NOTES | N11: TODAY'S NOTES | P11: WEEK THOUGHTS
B13: Roll/ Stretch | C13: FALSE | D13: Roll/ Stretch | E13: FALSE | F13: Roll/ Stretch | G13: FALSE | H13: Roll/ Stretch | I13: FALSE | J13: Roll/ Stretch | K13: FALSE | L13: Roll/ Stretch | M13: FALSE | N13: Roll/ Stretch | O13: FALSE | P13: =COUNTIF(B13:O13,True)/COUNTA(B13:O13)%/50 -> 0 | Q13: Recovery Score
B14: Refuel/ Rehydrate | C14: FALSE | D14: Refuel/ Rehydrate | E14: FALSE | F14: Refuel/ Rehydrate | G14: FALSE | H14: Refuel/ Rehydrate | I14: FALSE | J14: Refuel/ Rehydrate | K14: FALSE | L14: Refuel/ Rehydrate | M14: FALSE | N14: Refuel/ Rehydrate | O14: FALSE | P14: =COUNTIF(B14:O14,True)/COUNTA(B14:O14)%/50 -> 0
B15: Strength Work | D15: Strength Work | F15: Strength Work | H15: Strength Work | J15: Strength Work | L15: Strength Work | N15: Strength Work | P15: =COUNTIF(B15:O15,"Yes") -> 0 | Q15: Goal: 2-3
B16: Effort Level 1-10 | D16: Effort Level 1-10 | F16: Effort Level 1-10 | H16: Effort Level 1-10 | J16: Effort Level 1-10 | L16: Effort Level 1-10 | N16: Effort Level 1-10 | P16: =SUM(C16,E16,G16,I16,K16,M16,O16)/7 -> 0 | Q16: Avg. Goal: 3-6
A18: PUSH WEEK | B18: 46090 | D18: 46091 | F18: 46092 | H18: 46093 | J18: 46094 | L18: 46095 | N18: 46096 | P18: Planned Mileage | Q18: Actual Mileage
B19: 5 | C19: SPLITS | D19: 19 | E19: SPLITS | F19: 5 | G19: SPLITS | H19: 5 | I19: SPLITS | J19: 0 | K19: SPLITS | L19: 9 | M19: SPLITS | N19: 5 | O19: SPLITS
B20: Easy Run Start around 10:00 and work down to 9:00 IF IT FEELS EASY 4-6 miles | D20: LONG RUN WORKOUT 3 miles easy; 4, 3, 2, 1 mile w/ 1 mile FLOAT btwn; 3 miles easy 4 mile: 7:40-7:30 3 mile: 7:30-7:20 2 mile: 7:20-7:10 1 mile: 7:10-7:00 FLOAT: 8:50-8:20 PRACTICE FUELING CAN MOVE TO WEDNESDAY | F20: Easy Run Start around 10:00 and work down to 9:00 IF IT FEELS EASY 4-6 miles | H20: Easy Run Start around 10:00 and work down to 9:00 IF IT FEELS EASY 4-6 miles | J20: Day Off | L20: 5 miles of 3 min ON and 2 min FLOAT ON Pace: 7:15-6:45 FLOAT: 8:15-7:45 OPTIONAL | N20: Easy Run Start around 10:00 and work down to 9:00 IF IT FEELS EASY 4-6 miles | P20: =SUM(B19,D19,F19,H19,J19,L19,N19) -> 48
B21: AVG HR | C21: AVG PACE | D21: AVG HR | E21: AVG PACE | F21: AVG HR | G21: AVG PACE | H21: AVG HR | I21: AVG PACE | J21: AVG HR | K21: AVG PACE | L21: AVG HR | M21: AVG PACE | N21: AVG HR | O21: AVG PACE
A23: Prep/Fuel Like Race Week | B23: TODAY'S NOTES | D23: TODAY'S NOTES | F23: TODAY'S NOTES | H23: TODAY'S NOTES | J23: TODAY'S NOTES | L23: TODAY'S NOTES | N23: TODAY'S NOTES | P23: WEEK THOUGHTS
B25: Roll/ Stretch | C25: FALSE | D25: Roll/ Stretch | E25: FALSE | F25: Roll/ Stretch | G25: FALSE | H25: Roll/ Stretch | I25: FALSE | J25: Roll/ Stretch | K25: FALSE | L25: Roll/ Stretch | M25: FALSE | N25: Roll/ Stretch | O25: FALSE | P25: =COUNTIF(B25:O25,True)/COUNTA(B25:O25)%/50 -> 0 | Q25: Recovery Score
B26: Refuel/ Rehydrate | C26: FALSE | D26: Refuel/ Rehydrate | E26: FALSE | F26: Refuel/ Rehydrate | G26: FALSE | H26: Refuel/ Rehydrate | I26: FALSE | J26: Refuel/ Rehydrate | K26: FALSE | L26: Refuel/ Rehydrate | M26: FALSE | N26: Refuel/ Rehydrate | O26: FALSE | P26: =COUNTIF(B26:O26,True)/COUNTA(B26:O26)%/50 -> 0
B27: Strength Work | D27: Strength Work | F27: Strength Work | H27: Strength Work | J27: Strength Work | L27: Strength Work | N27: Strength Work | P27: =COUNTIF(B27:O27,"Yes") -> 0 | Q27: Goal: 2-3
B28: Effort Level 1-10 | D28: Effort Level 1-10 | F28: Effort Level 1-10 | H28: Effort Level 1-10 | J28: Effort Level 1-10 | L28: Effort Level 1-10 | N28: Effort Level 1-10 | P28: =SUM(C28,E28,G28,I28,K28,M28,O28)/7 -> 0 | Q28: Avg. Goal: 3-6
A30: TRAVEL/ LIMITED WEEK | B30: 46097 | D30: 46098 | F30: 46099 | H30: 46100 | J30: 46101 | L30: 46102 | N30: 46103 | P30: Planned Mileage | Q30: Actual Mileage
B31: 4 | C31: SPLITS | D31: 8 | E31: SPLITS | F31: 4 | G31: SPLITS | H31: 5 | I31: SPLITS | J31: 0 | K31: SPLITS | L31: 14 | M31: SPLITS | N31: 0 | O31: SPLITS
B32: 3-5 Miles Easy Run OR Day Off | D32: 5x1 mile @ 7:00-6:30 w/ 2 min walk/jog rest | F32: 3-5 Miles Easy Run OR Day Off | H32: 12x200m @ 50-45s w/ 200m jog rest btwn OR 3 miles of 1 min FAST and 90s JOG | J32: Day Off | L32: Easy Long Run 8-14 MILES | N32: Day Off | P32: =SUM(B31,D31,F31,H31,J31,L31,N31) -> 35
B33: AVG HR | C33: AVG PACE | D33: AVG HR | E33: AVG PACE | F33: AVG HR | G33: AVG PACE | H33: AVG HR | I33: AVG PACE | J33: AVG HR | K33: AVG PACE | L33: AVG HR | M33: AVG PACE | N33: AVG HR | O33: AVG PACE
A35: Focus HEAVILY on Rolling/ Stretching/ Recovery | B35: TODAY'S NOTES | D35: TODAY'S NOTES | F35: TODAY'S NOTES | H35: TODAY'S NOTES | J35: TODAY'S NOTES | L35: TODAY'S NOTES | N35: TODAY'S NOTES | P35: WEEK THOUGHTS
B37: Roll/ Stretch | C37: FALSE | D37: Roll/ Stretch | E37: FALSE | F37: Roll/ Stretch | G37: FALSE | H37: Roll/ Stretch | I37: FALSE | J37: Roll/ Stretch | K37: FALSE | L37: Roll/ Stretch | M37: FALSE | N37: Roll/ Stretch | O37: FALSE | P37: =COUNTIF(B37:O37,True)/COUNTA(B37:O37)%/50 -> 0 | Q37: Recovery Score
B38: Refuel/ Rehydrate | C38: FALSE | D38: Refuel/ Rehydrate | E38: FALSE | F38: Refuel/ Rehydrate | G38: FALSE | H38: Refuel/ Rehydrate | I38: FALSE | J38: Refuel/ Rehydrate | K38: FALSE | L38: Refuel/ Rehydrate | M38: FALSE | N38: Refuel/ Rehydrate | O38: FALSE | P38: =COUNTIF(B38:O38,True)/COUNTA(B38:O38)%/50 -> 0
B39: Strength Work | D39: Strength Work | F39: Strength Work | H39: Strength Work | J39: Strength Work | L39: Strength Work | N39: Strength Work | P39: =COUNTIF(B39:O39,"Yes") -> 0 | Q39: Goal: 2-3
B40: Effort Level 1-10 | D40: Effort Level 1-10 | F40: Effort Level 1-10 | H40: Effort Level 1-10 | J40: Effort Level 1-10 | L40: Effort Level 1-10 | N40: Effort Level 1-10 | P40: =SUM(C40,E40,G40,I40,K40,M40,O40)/7 -> 0 | Q40: Avg. Goal: 3-6
A42: TRAVEL/ LIMITED WEEK | B42: 46104 | D42: 46105 | F42: 46106 | H42: 46107 | J42: 46108 | L42: 46109 | N42: 46110 | P42: Planned Mileage | Q42: Actual Mileage
B43: 4 | C43: SPLITS | D43: 8 | E43: SPLITS | F43: 4 | G43: SPLITS | H43: 5 | I43: SPLITS | J43: 0 | K43: SPLITS | L43: 0 | M43: SPLITS | N43: 20 | O43: SPLITS
B44: 3-5 Miles Easy Run OR Day Off | D44: 10x800m @ 3:30-3:10 w/ 90s walk/jog rest btwn | F44: 3-5 Miles Easy Run OR Day Off | H44: 12x200m @ 50-45s w/ 200m jog rest btwn OR 3 miles of 1 min FAST and 90s JOG | J44: Day Off | L44: Day Off | N44: Easy Long Run 16-20 miles! PRACTICE FUELING | P44: =SUM(B43,D43,F43,H43,J43,L43,N43) -> 41
B45: AVG HR | C45: AVG PACE | D45: AVG HR | E45: AVG PACE | F45: AVG HR | G45: AVG PACE | H45: AVG HR | I45: AVG PACE | J45: AVG HR | K45: AVG PACE | L45: AVG HR | M45: AVG PACE | N45: AVG HR | O45: AVG PACE
A47: Focus HEAVILY on Rolling/ Stretching/ Recovery | B47: TODAY'S NOTES | D47: TODAY'S NOTES | F47: TODAY'S NOTES | H47: TODAY'S NOTES | J47: TODAY'S NOTES | L47: TODAY'S NOTES | N47: TODAY'S NOTES | P47: WEEK THOUGHTS
B49: Roll/ Stretch | C49: FALSE | D49: Roll/ Stretch | E49: FALSE | F49: Roll/ Stretch | G49: FALSE | H49: Roll/ Stretch | I49: FALSE | J49: Roll/ Stretch | K49: FALSE | L49: Roll/ Stretch | M49: FALSE | N49: Roll/ Stretch | O49: FALSE | P49: =COUNTIF(B49:O49,True)/COUNTA(B49:O49)%/50 -> 0 | Q49: Recovery Score
B50: Refuel/ Rehydrate | C50: FALSE | D50: Refuel/ Rehydrate | E50: FALSE | F50: Refuel/ Rehydrate | G50: FALSE | H50: Refuel/ Rehydrate | I50: FALSE | J50: Refuel/ Rehydrate | K50: FALSE | L50: Refuel/ Rehydrate | M50: FALSE | N50: Refuel/ Rehydrate | O50: FALSE | P50: =COUNTIF(B50:O50,True)/COUNTA(B50:O50)%/50 -> 0
B51: Strength Work | D51: Strength Work | F51: Strength Work | H51: Strength Work | J51: Strength Work | L51: Strength Work | N51: Strength Work | P51: =COUNTIF(B51:O51,"Yes") -> 0 | Q51: Goal: 2-3
...

Sheet April 
A1: ='March '!A1 -> STRAVA | B1: A P R I L | H1: MONTH GOAL➡️ | J1: This month we will finalize feeling solid at race pace! Recover well post travel and focus on the little things as we execute these last few weeks!
B2: Warm-Up Distance➡️ | C2: ='March '!C2 -> 1.5 mile | D2: Warm-Up & Cool Down Routine | F2: Rolling Routine
B3: Cool Down Distance➡️ | C3: ='March '!C3 -> 1.5 mile | F3: Stretching Routine
B4: Monday | D4: Tuesday | F4: Wednesday | H4: Thursday | J4: Friday | L4: Saturday | N4: Sunday | P4: Planned Mileage | Q4: Actual Mileage
B5: ='March '!B5 -> EASY RUN | D5: ='March '!D5 -> HARD WORKOUT & STRENGTH | F5: ='March '!F5 -> EASY RUN | H5: ='March '!H5 -> HARD WORKOUT & STRENGTH | J5: ='March '!J5 -> REST | L5: ='March '!L5 -> LONG RUN | N5: ='March '!N5 -> REST OR EASY RUN
A6: PEAK WEEK | B6: 46111 | D6: 46112 | F6: 46113 | H6: 46114 | J6: 46115 | L6: 46116 | N6: 46117 | P6: =SUM(B7,D7,F7,H7,J7,L7,N7) -> 49
B7: 5 | C7: SPLITS | D7: 10 | E7: SPLITS | F7: 5 | G7: SPLITS | H7: 3 | I7: SPLITS | J7: 21 | K7: SPLITS | L7: 0 | M7: SPLITS | N7: 5 | O7: SPLITS
B8: Easy Run 10:00 down to 9:00 IF IT FEELS EASY 4-6 miles | D8: 7x1 mile w/ 2 min jog rest btwn 1st 3: 7:30-7:20 2nd 2: 7:20-7:10 Last 2: 7:10-7:00 | F8: Easy Run 10:00 down to 9:00 IF IT FEELS EASY 4-6 miles | H8: Easy Run | J8: LAST LONG RUN WORKOUT 3 miles easy; 4x4 mile w/ 800m jog rest btwn; 1 mile easy 1st 4: 7:50-7:35 2nd 4: 7:45-7:30 3rd 4: 7:35-7:25 3rd 4: 7:20-7:10 PRACTICE FUELING | L8: Day Off | N8: Easy Run Start around 10:00 and work down to 9:00 IF IT FEELS EASY 4-6 miles
B9: AVG HR | C9: AVG PACE | D9: AVG HR | E9: AVG PACE | F9: AVG HR | G9: AVG PACE | H9: AVG HR | I9: AVG PACE | J9: AVG HR | K9: AVG PACE | L9: AVG HR | M9: AVG PACE | N9: AVG HR | O9: AVG PACE
A11: Prep/Fuel Like Race Week | B11: TODAY'S NOTES | D11: TODAY'S NOTES | F11: TODAY'S NOTES | H11: TODAY'S NOTES | J11: TODAY'S NOTES | L11: TODAY'S NOTES | N11: TODAY'S NOTES | P11: WEEK THOUGHTS
B13: Roll/ Stretch | C13: FALSE | D13: Roll/ Stretch | E13: FALSE | F13: Roll/ Stretch | G13: FALSE | H13: Roll/ Stretch | I13: FALSE | J13: Roll/ Stretch | K13: FALSE | L13: Roll/ Stretch | M13: FALSE | N13: Roll/ Stretch | O13: FALSE | P13: =COUNTIF(B13:O13,True)/COUNTA(B13:O13)%/50 -> 0 | Q13: Recovery Score
B14: Refuel/ Rehydrate | C14: FALSE | D14: Refuel/ Rehydrate | E14: FALSE | F14: Refuel/ Rehydrate | G14: FALSE | H14: Refuel/ Rehydrate | I14: FALSE | J14: Refuel/ Rehydrate | K14: FALSE | L14: Refuel/ Rehydrate | M14: FALSE | N14: Refuel/ Rehydrate | O14: FALSE | P14: =COUNTIF(B14:O14,True)/COUNTA(B14:O14)%/50 -> 0
B15: Strength Work | D15: Strength Work | F15: Strength Work | H15: Strength Work | J15: Strength Work | L15: Strength Work | N15: Strength Work | P15: =COUNTIF(B15:O15,"Yes") -> 0 | Q15: Goal: 2-3
B16: Effort Level 1-10 | D16: Effort Level 1-10 | F16: Effort Level 1-10 | H16: Effort Level 1-10 | J16: Effort Level 1-10 | L16: Effort Level 1-10 | N16: Effort Level 1-10 | P16: =SUM(C16,E16,G16,I16,K16,M16,O16)/7 -> 0 | Q16: Avg. Goal: 3-6
A18: REST WEEK | B18: 46118 | D18: 46119 | F18: 46120 | H18: 46121 | J18: 46122 | L18: 46123 | N18: 46124 | P18: Planned Mileage | Q18: Actual Mileage
B19: 4 | C19: SPLITS | D19: 11 | E19: SPLITS | F19: 4 | G19: SPLITS | H19: 6 | I19: SPLITS | J19: 0 | K19: SPLITS | L19: 12 | M19: SPLITS | N19: 0 | O19: SPLITS
B20: Easy Run 10:00 down to 9:00 IF IT FEELS EASY | D20: 8 miles of 3 min ON and 2 min FLOAT ON Pace: 7:20-7:00 FLOAT: 8:20-8:00 | F20: Easy Run 10:00 down to 9:00 IF IT FEELS EASY | H20: HILLS 3 miles of 60-90s UP @ 90% w/ walk/jog back down TREADMILL (3-4% incline): 60-90s UP @ 6:50-6:30 pace w/ 90s standing rest btwn | J20: Day Off | L20: SUPER EASY LONG RUN | N20: Day Off | P20: =SUM(B19,D19,F19,H19,J19,L19,N19) -> 37
B21: AVG HR | C21: AVG PACE | D21: AVG HR | E21: AVG PACE | F21: AVG HR | G21: AVG PACE | H21: AVG HR | I21: AVG PACE | J21: AVG HR | K21: AVG PACE | L21: AVG HR | M21: AVG PACE | N21: AVG HR | O21: AVG PACE
A23: Focus HEAVILY on Rolling/ Stretching/ Recovery | B23: TODAY'S NOTES | D23: TODAY'S NOTES | F23: TODAY'S NOTES | H23: TODAY'S NOTES | J23: TODAY'S NOTES | L23: TODAY'S NOTES | N23: TODAY'S NOTES | P23: WEEK THOUGHTS
B25: Roll/ Stretch | C25: FALSE | D25: Roll/ Stretch | E25: FALSE | F25: Roll/ Stretch | G25: FALSE | H25: Roll/ Stretch | I25: FALSE | J25: Roll/ Stretch | K25: FALSE | L25: Roll/ Stretch | M25: FALSE | N25: Roll/ Stretch | O25: FALSE | P25: =COUNTIF(B25:O25,True)/COUNTA(B25:O25)%/50 -> 0 | Q25: Recovery Score
